<?xml version="1.0"?>
<robot xmlns:xacro="http://www.ros.org/wiki/xacro" name="diff_drive_robot">

  <!--
    差速小车模型 — Phase 1 2D导航验证
    搭载 Livox Mid360 + IMU
  -->

  <xacro:include filename="$(find pnc_nav_sim)/urdf/sensors/livox_mid360.urdf.xacro"/>
  <xacro:include filename="$(find pnc_nav_sim)/urdf/sensors/imu.urdf.xacro"/>

  <!-- 参数 -->
  <xacro:property name="chassis_length" value="0.4"/>
  <xacro:property name="chassis_width" value="0.3"/>
  <xacro:property name="chassis_height" value="0.15"/>
  <xacro:property name="wheel_radius" value="0.05"/>
  <xacro:property name="wheel_width" value="0.03"/>
  <xacro:property name="wheel_separation" value="0.32"/>

  <!-- Base Footprint (地面投影) -->
  <link name="base_footprint"/>

  <!-- Base Link -->
  <link name="base_link">
    <visual>
      <geometry>
        <box size="${chassis_length} ${chassis_width} ${chassis_height}"/>
      </geometry>
      <material name="grey">
        <color rgba="0.6 0.6 0.6 1.0"/>
      </material>
    </visual>
    <collision>
      <geometry>
        <box size="${chassis_length} ${chassis_width} ${chassis_height}"/>
      </geometry>
    </collision>
    <inertial>
      <mass value="5.0"/>
      <inertia ixx="0.05" ixy="0" ixz="0" iyy="0.08" iyz="0" izz="0.1"/>
    </inertial>
  </link>

  <joint name="base_footprint_joint" type="fixed">
    <parent link="base_footprint"/>
    <child link="base_link"/>
    <origin xyz="0 0 ${wheel_radius + chassis_height/2}" rpy="0 0 0"/>
  </joint>

  <!-- 左轮 -->
  <link name="left_wheel">
    <visual>
      <geometry>
        <cylinder radius="${wheel_radius}" length="${wheel_width}"/>
      </geometry>
      <material name="black">
        <color rgba="0.1 0.1 0.1 1.0"/>
      </material>
    </visual>
    <collision>
      <geometry>
        <cylinder radius="${wheel_radius}" length="${wheel_width}"/>
      </geometry>
    </collision>
    <inertial>
      <mass value="0.5"/>
      <inertia ixx="0.0005" ixy="0" ixz="0" iyy="0.0005" iyz="0" izz="0.001"/>
    </inertial>
  </link>

  <joint name="left_wheel_joint" type="continuous">
    <parent link="base_link"/>
    <child link="left_wheel"/>
    <origin xyz="0 ${wheel_separation/2} ${-chassis_height/2}" rpy="${-pi/2} 0 0"/>
    <axis xyz="0 0 1"/>
  </joint>

  <!-- 右轮 -->
  <link name="right_wheel">
    <visual>
      <geometry>
        <cylinder radius="${wheel_radius}" length="${wheel_width}"/>
      </geometry>
      <material name="black">
        <color rgba="0.1 0.1 0.1 1.0"/>
      </material>
    </visual>
    <collision>
      <geometry>
        <cylinder radius="${wheel_radius}" length="${wheel_width}"/>
      </geometry>
    </collision>
    <inertial>
      <mass value="0.5"/>
      <inertia ixx="0.0005" ixy="0" ixz="0" iyy="0.0005" iyz="0" izz="0.001"/>
    </inertial>
  </link>

  <joint name="right_wheel_joint" type="continuous">
    <parent link="base_link"/>
    <child link="right_wheel"/>
    <origin xyz="0 ${-wheel_separation/2} ${-chassis_height/2}" rpy="${-pi/2} 0 0"/>
    <axis xyz="0 0 1"/>
  </joint>

  <!-- 万向轮 (前) -->
  <link name="caster_wheel">
    <visual>
      <geometry>
        <sphere radius="${wheel_radius * 0.5}"/>
      </geometry>
      <material name="black"/>
    </visual>
    <collision>
      <geometry>
        <sphere radius="${wheel_radius * 0.5}"/>
      </geometry>
    </collision>
    <inertial>
      <mass value="0.1"/>
      <inertia ixx="0.00001" ixy="0" ixz="0" iyy="0.00001" iyz="0" izz="0.00001"/>
    </inertial>
  </link>

  <joint name="caster_joint" type="fixed">
    <parent link="base_link"/>
    <child link="caster_wheel"/>
    <origin xyz="${chassis_length/2 - 0.05} 0 ${-chassis_height/2 - wheel_radius*0.5}" rpy="0 0 0"/>
  </joint>

  <!-- 差速驱动插件 -->
  <gazebo>
    <plugin name="diff_drive_controller" filename="libgazebo_ros_diff_drive.so">
      <ros>
        <remapping>cmd_vel:=cmd_vel</remapping>
        <remapping>odom:=odom</remapping>
      </ros>
      <left_joint>left_wheel_joint</left_joint>
      <right_joint>right_wheel_joint</right_joint>
      <wheel_separation>${wheel_separation}</wheel_separation>
      <wheel_diameter>${wheel_radius * 2}</wheel_diameter>
      <max_wheel_torque>10.0</max_wheel_torque>
      <max_wheel_acceleration>2.0</max_wheel_acceleration>
      <publish_odom>true</publish_odom>
      <publish_odom_tf>true</publish_odom_tf>
      <publish_wheel_tf>true</publish_wheel_tf>
      <odometry_frame>odom</odometry_frame>
      <robot_base_frame>base_footprint</robot_base_frame>
      <update_rate>50.0</update_rate>
    </plugin>
  </gazebo>

  <!-- 传感器：Livox Mid360 -->
  <xacro:livox_mid360
    parent_link="base_link"
    xyz="0 0 ${chassis_height/2 + 0.05}"
    rpy="0 0 0"
    topic="/livox/pointcloud"
    frame="livox_frame"/>

  <!-- 传感器：IMU -->
  <xacro:imu_sensor
    parent_link="base_link"
    xyz="0 0 0"
    rpy="0 0 0"
    topic="/imu"
    frame="imu_link"
    update_rate="200"/>

</robot>
